Workbook

Sheet Application_form
A1: Application ID: | G1: (For office use)
A3: APPLICATION FORM FOR FINANCIAL ASSISTANCE UNDER PRIME MINISTERS EMPLOYMENT GENERATION PROGRAMME (PMEGP)
T21: Khadi & V.I. Commission
T22: Khadi & V.I.Board
T23: District Industries Center
T24: District Industries Center
A54: 12 | B54: Name of the project / business activity proposed :
A56: 13 | B56: Amount of loan required (in Rs.)
B57: Building Type | C57: Capital Expenditure Loan
C58: Workshed Building etc. | D58: Machinery/ Equipment/Furniture | E58: Pre Operative Cost | F58: Working Capital / Cash Credit Limit | G58: Total
B59: =INDEX(DataSheet!L91:L93,DataSheet!M91,B1) -> Rented | C59: =DataSheet!H48 -> 0 | D59: =DataSheet!H67+DataSheet!H72 -> 0 | E59: =DataSheet!H70+DataSheet!H74 -> 0 | F59: =DataSheet!H76 -> 0 | G59: =SUM(C59:F59) -> 0
A60: 14 | B60: Details of earlier or current Loan/Grant and subsidy availed from Central/State Govt. Scheme/ or any other Similar Scheme.
B61: Activity of the Project with Address | E61: Amount | F61: Year of Sanction
B63: I certify that all information furnished by me is true; and that I and any of my dependent have not borrowed any money under subsidy linked scheme from any Central / State Government or bank for establishing any such project
B65: Place:
B66: Date: | G66: Signature of the Applicant
B68: For Official Use only: | D68: (Rejected / to be placed before District Task force Committee)
B69: Reason (if Rejected):
B72: Place: | F72: Signature, Name & Designation of Officer
B73: Date:
B76: NOTE
B77: • Own contribution must be invested 5% for SC/ST/OBC/PHC/woman/ Ex-serviceman/ North East Reason/Hill Boarder Area and 10% for General • Total Project Cost should not exceed 25 lakhs for Manufacturing unit and 10 lakhs for service unit. • Applicant will not be entitled for additional Margin Money(Subsidy) in case of Own Contribution over and above the prescribed limit. • VIIIth pass for Manufacturing Unit above Rs.10 lakhs project cost and under Service Sector above Rs.5 lakhs • Application should be submitted complete in all respect along with attested copies of the following documents: 1. Certificate of qualification-academic and technical (if project cost above 5 lakhs under service industry or above 10 lakhs under Manufacturing industry) 2. Relevant Certificate for SC/ST/OBC/Minority/Ex-Servicemen/PHC 3. if Entrepreneur Development programme(EDP) training undergone (at least for two weeks) then submit photocopy of the certificate

Sheet DataSheet
A1: DATA INPUT SHEET
A5: Preference for sponsoring agency of the project : | H5: (mark √ )
A6: Unit Location (As per revenue record) : | H6: (mark √ )
B7: KVIC | C7: =IF(DataSheet!M59=1,"√"," ") -> √ | D7: KVIB | E7: =IF(DataSheet!M59=2,"√"," ") | F7: DIC | G7: =IF(DataSheet!M59=3,"√"," ") | H7: COIR Board | J7: =IF(DataSheet!M59=4,"√"," ")
A8: 1.1 | B8: Name of the Applicant/Institution
A10: 1.2
A12: 2 | B12: Gender | D12: Male | E12: =IF(DataSheet!M55=1,"√"," ") -> √ | F12: Female | G12: =IF(DataSheet!M55=2,"√"," ") | H12: Transgender | I12: =IF(DataSheet!M55=3,"√"," ")
A13: 3 | B13: Address of the Proposed location of Unit: | F13: Rural | G13: =IF(DataSheet!M64=1,"√"," ") -> √ | H13: Urban | I13: =IF(DataSheet!M64<>1,"√"," ")
B16: Taluk/Block:
B17: District: | G17: Pin:
B18: State:
B19: Email: | F19: Mobile: | U19: Urban
A21: 4 | B21: Qualification
B22: Academic | E22: Technical
B23: =INDEX(DataSheet!L83:L89,DataSheet!M83) -> 12th Pass
A25: 5 | B25: Whether the applicant belongs to (mark √) | L25: =IF(DataSheet!M59=4,IF(AND(DataSheet!M56=1,DataSheet!M70=8),15%,25%),IF(AND(DataSheet!M56=1,DataSheet!M70=8),25%,35%)) -> 0.35
B26: SC | C26: ST | D26: OBC | E26: PHC | F26: Ex- Service man | G26: Minority | H26: Hill Border Area | I26: Aspirational Districts | J26: General
B27: =IF(DataSheet!M70=1,"√"," ") -> √ | C27: =IF(DataSheet!M70=2,"√"," ") | D27: =IF(DataSheet!M70=3,"√"," ") | E27: =IF(DataSheet!M70=4,"√"," ") | F27: =IF(DataSheet!M70=5,"√"," ") | G27: =IF(DataSheet!M70=6,"√"," ") | H27: =IF(DataSheet!M70=7,"√"," ") | I27: =IF(DataSheet!M70=8,"√"," ") | J27: =IF(DataSheet!M70=9,"√"," ")
A29: 6 | B29: Whether the project (mark √) | F29: Manufacturing Unit | G29: =IF(DataSheet!M80=1,"√"," ") -> √ | H29: Service Unit | I29: =IF(DataSheet!M80=2,"√"," ")
A31: 8 | B31: Name of the project / business activity proposed :
B34: Legal Status:
B36: Land | M36: =L59:L62 -> #VALUE!
B39: BUILDING DETAILS
B40: Particulars | F40: Area | G40: Rate/Sq.ft | H40: Amount in Rs.
B41: 2 Floor Building | H41: =IF(F41>=1,F41*G41,G41) -> 0
H42: =IF(F42>=1,F42*G42,G42) -> 0
H43: =IF(F43>=1,F43*G43,G43) -> 0
H44: =IF(F44>=1,F44*G44,G44) -> 0
H45: =IF(F45>=1,F45*G45,G45) -> 0
H46: =IF(F46>=1,F46*G46,G46) -> 0
H47: =IF(F47>=1,F47*G47,G47) -> 0
H48: =SUM(H41:H47) -> 0
B52: MACHINERY DETAILS
B53: Particulars | F53: Qty. | G53: Rate | H53: Amount in Rs.
B54: CNC | H54: =IF(F54>=1,F54*G54,G54) -> 0
H55: =IF(F55>=1,F55*G55,G55) -> 0 | L55: Male | M55: 1 | Q55: =IF(IF(AND(DataSheet!M55=1,DataSheet!M70=9,DataSheet!M64=2),15%,25%),IF(AND(DataSheet!M55=1,DataSheet!M70=9,DataSheet!M64=1),25%,35%)) -> 0.35
H56: =IF(F56>=1,F56*G56,G56) -> 0 | L56: Female
H57: =IF(F57>=1,F57*G57,G57) -> 0 | L57: Transgender | R57: =IF(M64=2,IF(AND(M55=1,M70=9),15,25),IF(AND(M55=1,M70=9),25,35)) -> 35
H58: =IF(F58>=1,F58*G58,G58) -> 0 | R58: =IF(AND(M55=1,M70=9,M64=2),15,25) -> 25
H59: =IF(F59>=1,F59*G59,G59) -> 0 | L59: KVIC | M59: 1 | R59: =IF(AND(M55=1,M64=1,M70=9),35,25) -> 25
...

Sheet DPR_print
B1: PROJECT AT A GLANCE - TOP SHEET
A3: 1 | B3: =Project_Report!B9 -> Name of the Beneficiary | E3: =Project_Report!G9 -> 0
A6: 2 | B6: =Project_Report!B11 -> Constitution (legal Status) : | E6: =Project_Report!G11 -> Individual
A8: 3 | B8: =Project_Report!B14 -> Father's/Spouce's Name | E8: =DataSheet!B11 -> 0
A10: 4 | B10: =Project_Report!B16 -> Unit Address : | E10: =Project_Report!G16 -> 0
E11: =Project_Report!G17 -> 0
E12: =Project_Report!G18 -> Taluk/Block: | F12: =Project_Report!H18 -> 0
E13: =Project_Report!G19 -> District : | F13: =Project_Report!H19 -> 0
E14: =Project_Report!G20 -> Pin: | F14: =Project_Report!H20 -> 0 | G14: =Project_Report!I20 -> State: | H14: =DataSheet!C18 -> 0
E15: =Project_Report!G22 -> E-Mail : | F15: =DataSheet!C19 -> 0
E16: Mobile | F16: =DataSheet!G19 -> 0
A17: 5 | B17: Product and By Product | E17: =DPR_FRONT!B2
A19: 6 | B19: Cost of Project | D19: : | E19: Rs. | F19: =H119 -> 0
B20: Name of the project / business activity proposed : | E20: =DataSheet!B32 -> 0
A22: 7 | B22: Means of Finance
B23: Term Loan | E23: Rs. | F23: =H129 -> 0
B24: KVIC Margin Money | E24: Rs. | F24: =H131 -> 0
B25: Own Capital | E25: Rs. | F25: =H123 -> 0
A28: 8 | B28: Debt Service Coverage Ratio | D28: :
A31: 9 | B31: Pay Back Period | D31: : | F31: =DataSheet!F179 -> 5 | G31: Years
A34: 10 | B34: Project Implementation Period | D34: : | F34: =DataSheet!G181 -> 0 | G34: Months
A37: 11 | B37: Break Even Point | D37: :
A40: 12 | B40: Employment | D40: : | F40: =Project_Report!I69 -> 0
A43: 13 | B43: Power Requirement | D43: : | F43: =DataSheet!G154 -> 0
A46: 14 | B46: Major Raw materials | D46: : | E46: =DataSheet!B107&","&DataSheet!B108&","&DataSheet!B109 -> ,,
A48: 15 | B48: Estimated Annual Sales Turnover | D48: : | E48: Rs. | F48: =H191 -> 0
A50: DETAILED PROJECT REPORT
A51: 1 | B51: INTRODUCTION :
B53: =DataSheet!B234 -> 0
A67: 2 | B67: ABOUT THE BENEFICIARY :
B69: =DataSheet!B251 -> 0
A81: 3 | B81: COST OF PROJECT
B82: A. Fixed Capital Investment
B83: a. Land : | F83: =DataSheet!F36:G36 -> 0 | H83: Own
B85: b. Workshed | F85: Area Sq.ft | G85: Rate in Rs. | H85: Amt. In Rs.
B86: =DataSheet!B41:E41 -> 2 Floor Building | F86: =DataSheet!F41 -> 0 | G86: =DataSheet!G41 -> 0 | H86: =DataSheet!H41:I41 -> 0
B87: =DataSheet!B42:E42 -> 0 | F87: =DataSheet!F42 -> 0 | G87: =DataSheet!G42 -> 0 | H87: =DataSheet!H42:I42 -> 0
B88: =DataSheet!B43:E43 -> 0 | F88: =DataSheet!F43 -> 0 | G88: =DataSheet!G43 -> 0 | H88: =DataSheet!H43:I43 -> 0
B89: =DataSheet!B44:E44 -> 0 | F89: =DataSheet!F44 -> 0 | G89: =DataSheet!G44 -> 0 | H89: =DataSheet!H44:I44 -> 0
B90: =DataSheet!B45:E45 -> 0 | F90: =DataSheet!F45 -> 0 | G90: =DataSheet!G45 -> 0 | H90: =DataSheet!H45:I45 -> 0
...

Sheet Project_Report
A1: PROJECT REPORT FOR
A2: =UPPER(Application_form!B55)
I5: Affix latest
I6: attested
I7: Photograph
A9: 1 | B9: =IF(K10=1,"Name of the Beneficiary","Name of the Institution/Unit") -> Name of the Beneficiary | G9: =DataSheet!B9 -> 0
K10: 1 | M10: Individual
A11: 2 | B11: Constitution (legal Status) : | G11: =INDEX(M10:M14,K10) -> Individual
A14: 3 | B14: =IF(K10=1,"Father's/Spouce's Name","Contact Persons Name") -> Father's/Spouce's Name | G14: =#REF! -> #REF!
A16: 5 | B16: Unit Address : | G16: =DataSheet!B14 -> 0
G17: =DataSheet!B15 -> 0
G18: Taluk/Block: | H18: =DataSheet!D16 -> 0
G19: District : | H19: =DataSheet!D16 -> 0
G20: Pin: | H20: =DataSheet!H17 -> 0 | I20: State: | J20: =#REF! -> #REF!
G21: Phone : | H21: =#REF! -> #REF!
G22: E-Mail : | H22: =#REF! -> #REF!
A24: 6 | B24: Background of the Proprietor/Partners/Directors : | G24: Furnished detailed information in the DPR
A27: 7 | B27: Name of Business House/Group if any :
A31: 8 | B31: Details Other Companies/Units in the group :
B32: Other Companies / Units in the Group | I32: (Rs. in Lakhs)
B33: Name & Address | D33: Business | E33: Equity | F33: Reserves | G33: Loans | H33: Turnover | I33: *P.B.T | J33: **P.A.T
B34: of Company / Unit
B37: * Profit Before Tax | D37: ** Profit After Tax
E38: `
A41: 8.1 | B41: How the activity was financed so far : | F41: ( To be filled up in case of existining unit Only )
B42: *Source of Funds | D42: Security | E42: Rate of | F42: Repayment per | H42: Present O/s | J42: Amount of Default
E43: Interest | F43: Month | H43: ( Rs. in '000 ) | J43: (if any)
A50: 8.2 | B50: If the Unit is an ancillary one, undertaking to
B51: which it is catering and its address :
A56: 8.3 | B56: Employment : | G56: Present | I56: Proposed
B57: =DataSheet!B121:D121 -> Labor | I57: =DataSheet!E121 -> 0
B58: =DataSheet!B122:D122 -> 0 | I58: =DataSheet!E122 -> 0
B59: =DataSheet!B123:D123 -> 0 | I59: =DataSheet!E123 -> 0
B60: =DataSheet!B124:D124 -> 0 | I60: =DataSheet!E124 -> 0
B61: =DataSheet!B125:D125 -> 0 | I61: =DataSheet!E125 -> 0
B62: =DataSheet!B126:D126 -> 0 | I62: =DataSheet!E126 -> 0
B63: =DataSheet!B127:D127 -> 0 | I63: =DataSheet!E127 -> 0
B64: =DataSheet!B134:D134 -> 0 | I64: =DataSheet!E134 -> 0
B65: =DataSheet!B135:D135 -> 0 | I65: =DataSheet!E135 -> 0
B66: =DataSheet!B136:D136 -> 0 | I66: =DataSheet!E136 -> 0
...

Sheet DPR_FRONT
B1: Project Report on
B2: =UPPER(Application_form!B55)
B32: Prepared By:
B33: =#REF! -> #REF!
B34: =INDEX(Application_form!T21:T24,DataSheet!M59) -> Khadi & V.I. Commission
B35: =#REF! -> #REF!
B36: =#REF! -> #REF!
B37: =#REF! -> #REF! | E37: State: | F37: =#REF! -> #REF!
B38: e-Mail:
B39: Ph. No.: | F39: Fax:
